Workbook

Sheet Instructions
A1: Adrabetadex Provider Net-Cost Recovery Calculator - Instructions
A3: Purpose
A4: This workbook estimates provider net-cost recovery for Adrabetadex under selected reimbursement, site-of-care, payer, sourcing, and timing scenarios.
A6: Intended Users
A7: Area Reimbursement Managers
A8: Provider reimbursement directors
A9: Revenue cycle teams
A10: Pharmacy leadership
A11: Patient access teams
A13: What the Model Calculates
A14: drug acquisition cost per administration
A15: allowed drug reimbursement per administration
... A31: This workbook is for planning and educational purposes only. It does not guarantee coverage, coding, payment, or reimbursement. Providers are responsible for selecting appropriate codes, documenting services, and confirming payer-specific billing and reimbursement rules. Results are estimates based on entered assumptions and may vary by payer, contract, state Medicaid program, site of care, coding status, 340B treatment, and claim outcome.

Sheet Core Assumptions
A1: Core Assumptions
A3: Fixed Assumptions | B3: Value | D3: Dropdown Lists | E3: Values
A4: Vial size | B4: 900 mg | D4: siteOfCare | E4: HOPD
A5: Launch WAC per vial | B5: 39000 | E5: Physician Office
A6: Dosing cadence | B6: Every 2 weeks | E6: Other
A7: Dosing interval weeks | B7: 2
A8: Administrations per year | B8: 26 | D8: yesNo | E8: Yes
A9: Pre-ASP period administrations | B9: 13 | E9: No
A10: Annual gross WAC exposure | B10: =B5*B8
A11: Pre-ASP WAC exposure | B11: =B5*B9 | D11: carve | E11: Carve-in
A12: Medicare pre-ASP benchmark percentage | B12: 1.03 | E12: Carve-out
A13: Medicare pre-ASP payment per administration | B13: =B5*B12 | E13: Not applicable
A14: OPPS pass-through effective date | B14: 46388
A15: Permanent HCPCS effective date | B15: 46478 | D15: payer | E15: Commercial
A16: Default customer type | B16: 340B center of excellence | E16: Medicaid FFS
A17: Default site of care | B17: HOPD | E17: Medicaid Managed Care
A18: Default 340B status | B18: Yes | E18: Dual
E19: Medicare
A20: 340B Assumptions | B20: Value | E20: Mixed
A21: WAC | B21: =B5
A22: 340B discount assumption, primary | B22: 0.231 | D22: coding | E22: Pre-code / NOC
A23: 340B acquisition, primary | B23: =B21*(1-B22) | E23: Pass-through active
A24: 340B discount assumption, pediatric | B24: 0.171 | E24: Product-specific HCPCS active
A25: 340B acquisition, pediatric | B25: =B21*(1-B24)
D26: sourcing | E26: Buy-and-bill
A27: Editable Assumptions | B27: Default / Input | E27: White-bagging
A28: Commercial payer mix | B28: 0.5 | E28: Mixed
A29: Medicaid payer mix | B29: 0.5
A30: Dual / other payer mix | B30: 0 | D30: reimb | E30: WAC %
A31: Site of care | B31: HOPD | E31: AWP %
A32: 340B status | B32: Yes | E32: ASP %
A33: 340B carve-in / carve-out | B33: Carve-in | E33: Contracted rate
A34: Payer type | B34: Commercial | E34: Manual entry
A35: Coding status | B35: Pass-through active
A36: Sourcing model | B36: Buy-and-bill | D36: acq | E36: Pediatric 17.1%
A37: Reimbursement basis | B37: AWP % | E37: Pediatric 17.1%
A38: 340B acquisition assumption | B38: ='Scenario Selector'!$C$69 | E38: Manual entry
A39: White-bagging percentage | B39: ='Scenario Selector'!$C$51
A40: Denial rate | B40: ='Scenario Selector'!$C$52 | D40: pass | E40: Active
A41: Appeal recovery rate | B41: ='Scenario Selector'!$C$53 | E41: Not active
...

Sheet Scenario Selector
A1: Scenario Selector
A2: Select Scenario Preset | B2: Default 340B COE HOPD, Pass-Through Active
A4: Scenario Field | B4: Manual Override | C4: Preset Value | D4: Active Value
A5: Site of care | B5: HOPD | C5: =INDEX($B$32:$L$40,MATCH($B$2,$A$32:$A$40,0),1) | D5: =IF(B5<>"",B5,C5)
A6: Payer type | B6: Commercial | C6: =INDEX($B$32:$L$40,MATCH($B$2,$A$32:$A$40,0),2) | D6: =IF(B6<>"",B6,C6)
A7: 340B status | B7: Yes | C7: =INDEX($B$32:$L$40,MATCH($B$2,$A$32:$A$40,0),3) | D7: =IF(B7<>"",B7,C7)
A8: 340B treatment | B8: Carve-out | C8: =INDEX($B$32:$L$40,MATCH($B$2,$A$32:$A$40,0),4) | D8: =IF(B8<>"",B8,C8)
A9: Coding status | B9: Pass-through active | C9: =INDEX($B$32:$L$40,MATCH($B$2,$A$32:$A$40,0),5) | D9: =IF(B9<>"",B9,C9)
A10: OPPS pass-through status | B10: Active | C10: =INDEX($B$32:$L$40,MATCH($B$2,$A$32:$A$40,0),6) | D10: =IF(B10<>"",B10,C10)
A11: Sourcing model | B11: Buy-and-bill | C11: =INDEX($B$32:$L$40,MATCH($B$2,$A$32:$A$40,0),7) | D11: =IF(B11<>"",B11,C11)
A12: ASP status | B12: Pre-ASP | C12: =INDEX($B$32:$L$40,MATCH($B$2,$A$32:$A$40,0),8) | D12: =IF(B12<>"",B12,C12)
A13: Reimbursement basis | B13: WAC % | C13: =INDEX($B$32:$L$40,MATCH($B$2,$A$32:$A$40,0),9) | D13: =IF(B13<>"",B13,C13)
A14: 340B acquisition assumption | B14: Primary 23.1% | C14: =INDEX($B$32:$L$40,MATCH($B$2,$A$32:$A$40,0),10) | D14: =IF(B14<>"",B14,C14)
A15: Prior authorization status | B15: Confirmed | C15: =INDEX($B$32:$L$40,MATCH($B$2,$A$32:$A$40,0),11) | D15: =IF(B15<>"",B15,C15)
A18: Scenario Logic | B18: Selected preset fills Preset Value. Active Value uses Manual Override when provided, otherwise Preset Value.
A19: Default scenario | B19: 340B COE HOPD, Pass-Through Active
A31: Scenario Name | B31: Site of care | C31: Payer type | D31: 340B status | E31: 340B treatment | F31: Coding status | G31: OPPS pass-through status | H31: Sourcing model | I31: ASP status | J31: Reimbursement basis | K31: 340B acquisition assumption | L31: Prior authorization status
A32: Default 340B COE HOPD, Pass-Through Active | B32: HOPD | C32: Medicare | D32: Yes | E32: Carve-out | F32: Pass-through active | G32: Active | H32: Buy-and-bill | I32: Pre-ASP | J32: WAC % | K32: Primary 23.1% | L32: Confirmed
A33: 340B COE HOPD, Pre-Pass-Through | B33: HOPD | C33: Medicare | D33: Yes | E33: Carve-out | F33: Pre-code / NOC | G33: Not active | H33: Buy-and-bill | I33: Pre-ASP | J33: WAC % | K33: Primary 23.1% | L33: Not confirmed
A34: 340B COE HOPD, Product-Specific HCPCS Active | B34: HOPD | C34: Medicare | D34: Yes | E34: Carve-out | F34: Product-specific HCPCS active | G34: Not applicable | H34: Buy-and-bill | I34: ASP available | J34: ASP % | K34: Primary 23.1% | L34: Confirmed
A35: Commercial Buy-and-Bill, 340B HOPD | B35: HOPD | C35: Commercial | D35: Yes | E35: Carve-out | F35: Pass-through active | G35: Not applicable | H35: Buy-and-bill | I35: Pre-ASP | J35: Contracted rate | K35: Primary 23.1% | L35: Confirmed
A36: Commercial White-Bagging | B36: HOPD | C36: Commercial | D36: No | E36: Not applicable | F36: Pass-through active | G36: Not applicable | H36: White-bagging | I36: Pre-ASP | J36: Manual entry | K36: Manual entry | L36: Confirmed
A37: Medicaid Managed Care, 340B COE | B37: HOPD | C37: Medicaid Managed Care | D37: Yes | E37: Carve-in | F37: Pass-through active | G37: Not applicable | H37: Buy-and-bill | I37: Pre-ASP | J37: WAC % | K37: Primary 23.1% | L37: Confirmed
A38: Medicaid FFS, 340B COE | B38: HOPD | C38: Medicaid FFS | D38: Yes | E38: Carve-in | F38: Pass-through active | G38: Not applicable | H38: Buy-and-bill | I38: Pre-ASP | J38: WAC % | K38: Primary 23.1% | L38: Confirmed
A39: Non-340B Sensitivity | B39: HOPD | C39: Medicare | D39: No | E39: Not applicable | F39: Pass-through active | G39: Active | H39: Buy-and-bill | I39: Pre-ASP | J39: WAC % | K39: Manual entry | L39: Confirmed
A40: Physician Office Sensitivity | B40: Physician Office | C40: Commercial | D40: No | E40: Not applicable | F40: Pre-code / NOC | G40: Not applicable | H40: Mixed | I40: Pre-ASP | J40: WAC % | K40: Manual entry | L40: Not confirmed
A42: Numeric Preset Name | B42: White-bag % | C42: Denial % | D42: Appeal recovery % | E42: Days to payment | F42: Labor | G42: Pharmacy | H42: Billing/Admin | I42: Other non-drug | J42: Procedure revenue | K42: Wastage | L42: Financing % | M42: Mfr support | N42: Manual allowed | O42: Contracted rate | P42: AWP | Q42: ASP | R42: Manual 340B acq | S42: Reimbursement % | T42: Acquisition Assumption
A43: Base Case: 340B COE HOPD, Buy-and-Bill | B43: 0 | C43: 0.075 | D43: 0.6 | E43: 75 | F43: 750 | G43: 400 | H43: 300 | I43: 250 | J43: 500 | K43: 0 | L43: 0.08 | M43: 0 | N43: 40170 | O43: 39000 | P43: 46800 | Q43: 37050 | R43: 29991 | S43: 1.03 | T43: Primary 23.1%
A44: Conservative Case: Launch Friction / Manual Review | B44: 0 | C44: 0.15 | D44: 0.5 | E44: 120 | F44: 1000 | G44: 600 | H44: 500 | I44: 500 | J44: 400 | K44: 0 | L44: 0.1 | M44: 0 | N44: 40170 | O44: 37050 | P44: 46800 | Q44: 35100 | R44: 32331 | S44: 0.95 | T44: Pediatric 17.1%
A45: White-Bagging Case | B45: 1 | C45: 0.05 | D45: 0.7 | E45: 45 | F45: 750 | G45: 250 | H45: 250 | I45: 250 | J45: 500 | K45: 0 | L45: 0.08 | M45: 0 | N45: 0 | O45: 0 | P45: 46800 | Q45: 37050 | R45: 0 | S45: 0 | T45: Manual entry
A47: Numeric Preset Selector | B47: Manual Override? | C47: Active
A48: Selected Numeric Preset | B48: Base Case: 340B COE HOPD, Buy-and-Bill | C48: =B48
A50: Numeric Input | B50: Preset Value | C50: Active to Core
A51: White-bagging percentage (payer-driven toggle) | B51: =INDEX($B$43:$T$45,MATCH($B$48,$A$43:$A$45,0),1) | C51: =B51
A52: Denial rate | B52: =INDEX($B$43:$T$45,MATCH($B$48,$A$43:$A$45,0),2) | C52: =B52
A53: Appeal recovery rate | B53: =INDEX($B$43:$T$45,MATCH($B$48,$A$43:$A$45,0),3) | C53: =B53
A54: Days to payment | B54: =INDEX($B$43:$T$45,MATCH($B$48,$A$43:$A$45,0),4) | C54: =B54
A55: Labor cost per administration | B55: =INDEX($B$43:$T$45,MATCH($B$48,$A$43:$A$45,0),5) | C55: =B55
A56: Pharmacy handling cost per administration | B56: =INDEX($B$43:$T$45,MATCH($B$48,$A$43:$A$45,0),6) | C56: =B56
A57: Billing/admin cost per administration | B57: =INDEX($B$43:$T$45,MATCH($B$48,$A$43:$A$45,0),7) | C57: =B57
...

Sheet Calculation Engine
A1: Calculation Engine (Formula Driven)
A3: Input References | B3: Value
A4: Site_of_Care | B4: ='Scenario Selector'!$D$5
A5: Payer_Type | B5: ='Scenario Selector'!$D$6
A6: 340B_Status | B6: ='Scenario Selector'!$D$7
A7: 340B_Treatment | B7: ='Scenario Selector'!$D$8
A8: Coding_Status | B8: ='Scenario Selector'!$D$9
A9: OPPS_Pass_Through_Status | B9: ='Scenario Selector'!$D$10
A10: Sourcing_Model | B10: ='Scenario Selector'!$D$11
A11: ASP_Status | B11: ='Scenario Selector'!$D$12
A12: Reimbursement_Basis | B12: ='Scenario Selector'!$D$13
A13: 340B_Acquisition_Assumption | B13: ='Scenario Selector'!$D$14
A14: Prior_Authorization_Status | B14: ='Scenario Selector'!$D$15
A15: White_Bagging_Percentage | B15: ='Core Assumptions'!$B$39
A16: Denial_Rate | B16: ='Core Assumptions'!$B$40
A17: Appeal_Recovery_Rate | B17: ='Core Assumptions'!$B$41
A18: Days_To_Payment | B18: ='Core Assumptions'!$B$42
A19: Reimbursement_Percentage | B19: ='Core Assumptions'!$B$56
A20: WAC | B20: ='Core Assumptions'!$B$5
A21: AWP | B21: ='Core Assumptions'!$B$53
A22: ASP | B22: ='Core Assumptions'!$B$54
A23: Contracted_Rate | B23: ='Core Assumptions'!$B$52
A24: Manual_Allowed_Amount | B24: ='Core Assumptions'!$B$51
A25: Labor_Cost_Per_Admin | B25: ='Core Assumptions'!$B$43
A26: Pharmacy_Handling_Cost_Per_Admin | B26: ='Core Assumptions'!$B$44
A27: Billing_Admin_Cost_Per_Admin | B27: ='Core Assumptions'!$B$45
A28: Other_Non_Drug_Cost | B28: ='Core Assumptions'!$B$46
A29: Wastage_Cost_Per_Admin | B29: ='Core Assumptions'!$B$48
A30: Financing_Rate | B30: ='Core Assumptions'!$B$49
A31: Procedure_Revenue_Per_Dose | B31: ='Core Assumptions'!$B$47
A32: Manufacturer_Support_Per_Dose | B32: ='Core Assumptions'!$B$50
A33: Manual_340B_Acquisition | B33: ='Core Assumptions'!$B$55
A35: Model Outputs | B35: Value
A36: Annual_Doses | B36: =26
A37: Calculated_Annual_Doses | B37: =52/'Core Assumptions'!$B$7
A38: Pre_ASP_Doses | B38: =13
A39: Selected_340B_Acquisition | B39: =IF(B13="Primary 23.1%",'Core Assumptions'!$B$23,IF(B13="Pediatric 17.1%",'Core Assumptions'!$B$25,B33))
A40: Selected_Allowed_Drug_Reimbursement | B40: =IF(B12="WAC %",B20*B19,IF(B12="AWP %",B21*B19,IF(B12="ASP %",B22*B19,IF(B12="Contracted rate",B23,IF(B12="Manual entry",B24,0)))))
A41: Drug_Acquisition_Per_Dose | B41: =IF(B10="White-bagging",0,IF(B10="Mixed",(1-B15)*IF(B6="Yes",B39,B20),IF(B6="Yes",B39,B20)))
A42: Allowed_Drug_Reimbursement_Per_Dose | B42: =IF(B10="White-bagging",0,IF(B10="Mixed",(1-B15)*B40,B40))
...

Sheet ARM Output
A1: Adrabetadex Provider Net-Cost Recovery Summary
A2: Provider-facing output summary for selected scenario.
A3: Header | B3: Value | E3: Header | F3: Value
A4: Product | B4: Adrabetadex | E4: Sourcing model | F4: ='Scenario Selector'!$D$11
A5: Scenario name | B5: ='Scenario Selector'!$B$2 | E5: Pass-through status | F5: ='Scenario Selector'!$D$10
A6: Date generated | B6: =TODAY() | E6: Reimbursement basis | F6: ='Scenario Selector'!$D$13
A7: Site type | B7: ='Scenario Selector'!$D$5
A8: Payer type | B8: ='Scenario Selector'!$D$6
A9: 340B status | B9: ='Scenario Selector'!$D$7
A10: Coding status | B10: ='Scenario Selector'!$D$9
A12: Selected Scenario Summary | B12: Value | D12: Per-Dose Economics | E12: Value
A13: Site of care | B13: ='Scenario Selector'!$D$5 | D13: Drug acquisition per dose | E13: ='Calculation Engine'!$B$41
A14: Payer type | B14: ='Scenario Selector'!$D$6 | D14: Allowed drug reimbursement per dose | E14: ='Calculation Engine'!$B$42
A15: 340B status | B15: ='Scenario Selector'!$D$7 | D15: Drug spread per dose | E15: ='Calculation Engine'!$B$43
A16: Coding status | B16: ='Scenario Selector'!$D$9 | D16: Procedure revenue per dose | E16: ='Calculation Engine'!$B$31
A17: Pass-through status | B17: ='Scenario Selector'!$D$10 | D17: Non-drug operating cost per dose | E17: ='Calculation Engine'!$B$44
A18: Sourcing model | B18: ='Scenario Selector'!$D$11 | D18: Denial drag per dose | E18: ='Calculation Engine'!$B$45
A19: Reimbursement basis | B19: ='Scenario Selector'!$D$13 | D19: Financing drag per dose | E19: ='Calculation Engine'!$B$46
D20: Net operating margin per dose | E20: ='Calculation Engine'!$B$47
D21: Break-even support per dose | E21: ='Calculation Engine'!$B$51
A22: Annual Economics | B22: Value | D22: Risk Flags | E22: Result | F22: Explanation
A23: Annual administrations | B23: ='Calculation Engine'!$B$36 | D23: Margin risk | E23: ='Calculation Engine'!$B$62 | F23: =IF(E23="High margin risk","Per-dose margin is negative.",IF(E23="Moderate margin risk","Per-dose margin is positive but narrow.","Per-dose margin has stronger cushion."))
A24: Annual drug acquisition | B24: ='Calculation Engine'!$B$59 | D24: Cash exposure risk | E24: ='Calculation Engine'!$B$63 | F24: =IF(E24="High cash exposure","Days-to-payment and acquisition burden create elevated float exposure.",IF(E24="Moderate cash exposure","Monitor outstanding administrations and remittance timing.","Cash exposure appears manageable at current assumptions."))
A25: Annual allowed drug reimbursement | B25: ='Calculation Engine'!$B$60 | D25: Operational risk | E25: ='Calculation Engine'!$B$64 | F25: =IF(E25="High operational risk","Coding and PA readiness may disrupt clean claim payment.",IF(E25="Moderate operational risk","Strengthen denial management and payment cycle controls.","Operational assumptions are relatively stable."))
A26: Annual non-drug operating cost | B26: ='Calculation Engine'!$B$61
A27: Annual net contribution | B27: ='Calculation Engine'!$B$48
A28: Annual break-even support | B28: ='Calculation Engine'!$B$52
A29: Cash at risk | B29: ='Calculation Engine'!$B$50
A30: Annual 340B acquisition advantage | B30: ='Calculation Engine'!$B$57
A32: Customer Conversation Takeaways
A33: =IF('Scenario Selector'!$D$11="White-bagging","1. White-bagging reduces provider acquisition exposure.",IF('Scenario Selector'!$D$7="No","1. Non-340B acquisition creates higher cash exposure.",IF('Scenario Selector'!$D$9="Pre-code / NOC","1. Interim coding increases operational risk.","1. 340B acquisition materially improves provider economics.")))
A34: =IF('Scenario Selector'!$D$11="White-bagging","2. White-bagging removes provider drug reimbursement and drug spread.",IF('Scenario Selector'!$D$7="No","2. Margin depends heavily on allowed reimbursement, denial rate, and payment timing.",IF('Scenario Selector'!$D$9="Pre-code / NOC","2. NDC, invoice support, and medical-necessity documentation are required for clean claim processing.","2. Pass-through and permanent HCPCS timing reduce payment uncertainty across the launch bridge.")))
A35: =IF('Scenario Selector'!$D$11="White-bagging","3. Administration revenue and operational workflow remain important to evaluate.",IF('Scenario Selector'!$D$7="No","3. Break-even support may be required if net operating margin is negative.",IF('Scenario Selector'!$D$9="Pre-code / NOC","3. Permanent HCPCS timing should be reflected in site readiness planning.","3. Clean PA, NDC, billing, wastage, and 340B documentation are required to convert coverage into payment.")))
A39: Estimates are for planning purposes only and do not guarantee coverage, coding, payment, or reimbursement. Providers should verify coding, billing, payer rules, contract terms, and documentation requirements before claim submission.

Sheet Appendix Assumptions
A1: Appendix Assumptions
A3: Coding Assumptions | B3: Assumption | D3: Policy Caveats
A4: Launch coding | B4: Interim/NOC coding is required before product-specific HCPCS | D4: Coverage does not guarantee payment.
A5: HOPD interim code | B5: C9399 is used for HOPD OPPS interim unclassified billing when applicable | D5: Prior authorization is expected.
A6: Professional interim codes | B6: J3490 or J3590 are used when payer/product classification supports NOC professional billing | D6: Site-of-care review is expected.
A7: Permanent HCPCS | B7: Product-specific HCPCS is effective April 1, 2027 | D7: Commercial payers may require specialty pharmacy or white-bagging.
A8: NDC reporting | B8: NDC reporting is required for Medicaid PAD and required/important for commercial, manual pricing, and OPPS workflows | D8: Medicaid payment is state-specific.
A9: JW/JZ | B9: JW/JZ reporting is required where applicable for single-dose vial billing | D9: EPSDT may support pediatric medical necessity but does not establish provider payment.
A10: 340B modifier | B10: TB or payer-required 340B modifier is used where applicable | D10: ASP-based reimbursement must be updated when ASP becomes available.
A12: Reimbursement Assumptions | B12: Assumption | D12: 340B Compliance Caveats
A13: Pre-ASP benchmark | B13: 103% of WAC | D13: 340B status must be confirmed by the provider.
A14: WAC | B14: $39,000 | D14: Covered entity and child-site eligibility must be validated.
A15: Pre-ASP period | B15: First two quarters | D15: Medicaid carve-in/carve-out status must be confirmed.
... A18: Default customer | B18: 340B center of excellence | D18: Calculator output is not a 340B compliance determination.
A19: Default acquisition model | B19: 340B acquisition where applicable
A20: White-bagging (payer-driven) | B20: Drug acquisition and drug reimbursement to provider are $0 for the white-bagged portion
A21: Buy-and-bill | B21: Provider carries acquisition cost and bills drug reimbursement
A22: Mixed sourcing | B22: White-bagging percentage reduces both provider acquisition and provider drug reimbursement proportionally
A24: Hybrid PDF Approach | B24: Purpose
A25: Excel workbook | B25: Live formula engine and scenario calculator
A26: PDF summary | B26: Static one-page leave-behind generated from ARM Output tab
